
Running tests... 
----------------------------------------------------------------------
 test_login (__main__.TestLogin) ... FAIL (12.399829)s

======================================================================
FAIL [12.399829s]: __main__.TestLogin.test_login
----------------------------------------------------------------------
Traceback (most recent call last):
  File "c:/Users/Alireza/Pictures/Selenium/login3.py", line 41, in test_login
    self.fail(f"Login failed! Screenshot: {screenshot_path}")
AssertionError: Login failed! Screenshot: reports/screenshots/login_failed.png

----------------------------------------------------------------------
Ran 1 test in 0:00:16

FAILED
 (Failures=1)

Generating HTML reports... 
reports\Login_Test_Report___main__.TestLogin_2025-01-30_16-25-58.html
